Workbook

Sheet Cover
B2: TEST DOCUMENTATION
B3: Sistem Informasi Desa Pangombusan (Website)
B5: Document Title | C5: Test Scenario, Test Case & Bug Report
B6: Project | C6: Sistem Informasi Desa Pangombusan
B7: Version | C7: 1.0
B8: Prepared by (QA) | C8: Marshanda Kasih Simangunsong
B9: Test Date | C9: 05 – 07 Juni 2023 (Cycle 1); 09 Juni 2023 (Retest)
B10: Test Type | C10: Black Box – Functional Testing (manual)
B11: Test Level | C11: Unit / Function Level
B12: Environment | C12: Windows 11, Apache, MySQL, Google Chrome / Mozilla Firefox / Microsoft Edge
B13: Scope (In) | C13: Registrasi, Login, Kelola Berita, Pengumuman, Galeri, Saran, Surat Pengantar KTP (pengajuan & approval), Logout, Halaman publik, Kontrol akses dasar, Kompatibilitas browser
B14: Scope (Out) | C14: Performance testing, load testing, penetration testing menyeluruh
B15: Acceptance Basis | C15: Fungsi F-01 s.d. F-35 pada dokumen Testing proyek; aturan validasi tambahan (mis. password min. 8 karakter, NIK 16 digit) ditetapkan oleh tester sebagai acuan.
B17: Definisi Severity & Priority
B18: Critical | C18: Sistem crash / celah keamanan serius / data hilang; tidak ada workaround.
B19: High | C19: Fungsi utama tidak berjalan benar atau validasi data penting gagal; workaround sulit.
B20: Medium | C20: Fungsi berjalan sebagian / hasil kurang tepat; ada workaround.
B21: Low | C21: Masalah kosmetik / tampilan; tidak mempengaruhi fungsi.
B22: Priority | C22: Urgensi perbaikan oleh developer: High (segera), Medium (rilis berikutnya), Low (jika sempat).
B24: Bug Lifecycle | C24: Open → Fixed (siap retest) → Closed | jika retest gagal: Reopened
B26: Daftar Sheet
B27: Test Scenario | C27: Daftar skenario uji per modul + status otomatis
B28: Test Case | C28: Detail test case: langkah, data uji, expected vs actual, status, evidence
B29: Bug Report | C29: Daftar defect hasil pengujian beserta severity, status & evidence
B30: Test Summary | C30: Rekap hasil eksekusi & defect (otomatis dari sheet lain)
B32: Catatan: sel kuning (C8) = isi nama tester; otomatis terisi di kolom Tester pada Test Case & Bug Report. Kolom Evidence berisi nama file screenshot di folder /Evidence.

Sheet Test Scenario
A1: Test Scenario – Sistem Informasi Desa Pangombusan
A2: Status scenario dihitung otomatis dari hasil Test Case
A4: TS ID | B4: Module | C4: Test Scenario | D4: Function Ref | E4: Priority | F4: Total TC | G4: Passed | H4: Failed | I4: Scenario Status
A5: TS-01 | B5: Registrasi | C5: Verifikasi user dapat mendaftar akun dan sistem memvalidasi input registrasi | D5: F-01 | E5: High | F5: =COUNTIF('Test Case'!$B:$B,A5) -> 5 | G5: =COUNTIFS('Test Case'!$B:$B,A5,'Test Case'!$L:$L,"Pass") -> 3 | H5: =COUNTIFS('Test Case'!$B:$B,A5,'Test Case'!$L:$L,"Fail") -> 2 | I5: =IF(F5=0,"Not Run",IF(H5>0,"Failed","Passed")) -> Failed
A6: TS-02 | B6: Login | C6: Verifikasi admin/user dapat login dengan kredensial valid dan ditolak jika tidak valid | D6: F-02 | E6: High | F6: =COUNTIF('Test Case'!$B:$B,A6) -> 6 | G6: =COUNTIFS('Test Case'!$B:$B,A6,'Test Case'!$L:$L,"Pass") -> 6 | H6: =COUNTIFS('Test Case'!$B:$B,A6,'Test Case'!$L:$L,"Fail") -> 0 | I6: =IF(F6=0,"Not Run",IF(H6>0,"Failed","Passed")) -> Passed
A7: TS-03 | B7: Kelola Berita | C7: Verifikasi lihat, tambah, edit, dan hapus berita terbaru | D7: F-03 – F-06 | E7: High | F7: =COUNTIF('Test Case'!$B:$B,A7) -> 6 | G7: =COUNTIFS('Test Case'!$B:$B,A7,'Test Case'!$L:$L,"Pass") -> 4 | H7: =COUNTIFS('Test Case'!$B:$B,A7,'Test Case'!$L:$L,"Fail") -> 2 | I7: =IF(F7=0,"Not Run",IF(H7>0,"Failed","Passed")) -> Failed
A8: TS-04 | B8: Kelola Pengumuman | C8: Verifikasi tambah, edit, hapus, dan tampilan pengumuman | D8: F-10 – F-13 | E8: Medium | F8: =COUNTIF('Test Case'!$B:$B,A8) -> 4 | G8: =COUNTIFS('Test Case'!$B:$B,A8,'Test Case'!$L:$L,"Pass") -> 3 | H8: =COUNTIFS('Test Case'!$B:$B,A8,'Test Case'!$L:$L,"Fail") -> 1 | I8: =IF(F8=0,"Not Run",IF(H8>0,"Failed","Passed")) -> Failed
A9: TS-05 | B9: Surat Pengantar KTP – Pengajuan | C9: Verifikasi user dapat mengajukan surat pengantar KTP dengan data valid | D9: F-09, F-30 | E9: High | F9: =COUNTIF('Test Case'!$B:$B,A9) -> 4 | G9: =COUNTIFS('Test Case'!$B:$B,A9,'Test Case'!$L:$L,"Pass") -> 3 | H9: =COUNTIFS('Test Case'!$B:$B,A9,'Test Case'!$L:$L,"Fail") -> 1 | I9: =IF(F9=0,"Not Run",IF(H9>0,"Failed","Passed")) -> Failed
A10: TS-06 | B10: Surat Pengantar KTP – Approval | C10: Verifikasi admin dapat menyetujui / menolak dan melihat daftar approve/reject | D10: F-31 – F-34 | E10: High | F10: =COUNTIF('Test Case'!$B:$B,A10) -> 4 | G10: =COUNTIFS('Test Case'!$B:$B,A10,'Test Case'!$L:$L,"Pass") -> 4 | H10: =COUNTIFS('Test Case'!$B:$B,A10,'Test Case'!$L:$L,"Fail") -> 0 | I10: =IF(F10=0,"Not Run",IF(H10>0,"Failed","Passed")) -> Passed
A11: TS-07 | B11: Kelola Saran | C11: Verifikasi kirim, lihat, edit, hapus saran serta penanganan input berbahaya | D11: F-22 – F-25 | E11: Medium | F11: =COUNTIF('Test Case'!$B:$B,A11) -> 5 | G11: =COUNTIFS('Test Case'!$B:$B,A11,'Test Case'!$L:$L,"Pass") -> 4 | H11: =COUNTIFS('Test Case'!$B:$B,A11,'Test Case'!$L:$L,"Fail") -> 1 | I11: =IF(F11=0,"Not Run",IF(H11>0,"Failed","Passed")) -> Failed
A12: TS-08 | B12: Kelola Galeri | C12: Verifikasi tambah dan hapus foto galeri beserta validasi file | D12: F-18 – F-21 | E12: Medium | F12: =COUNTIF('Test Case'!$B:$B,A12) -> 3 | G12: =COUNTIFS('Test Case'!$B:$B,A12,'Test Case'!$L:$L,"Pass") -> 3 | H12: =COUNTIFS('Test Case'!$B:$B,A12,'Test Case'!$L:$L,"Fail") -> 0 | I12: =IF(F12=0,"Not Run",IF(H12>0,"Failed","Passed")) -> Passed
A13: TS-09 | B13: Logout | C13: Verifikasi logout mengakhiri sesi dengan benar | D13: F-35 | E13: High | F13: =COUNTIF('Test Case'!$B:$B,A13) -> 2 | G13: =COUNTIFS('Test Case'!$B:$B,A13,'Test Case'!$L:$L,"Pass") -> 1 | H13: =COUNTIFS('Test Case'!$B:$B,A13,'Test Case'!$L:$L,"Fail") -> 1 | I13: =IF(F13=0,"Not Run",IF(H13>0,"Failed","Passed")) -> Failed
A14: TS-10 | B14: Halaman Publik | C14: Verifikasi profil desa, kontak, visi misi, dan struktur pemerintahan dapat dilihat guest | D14: F-07, F-08, F-14, F-26 | E14: Low | F14: =COUNTIF('Test Case'!$B:$B,A14) -> 1 | G14: =COUNTIFS('Test Case'!$B:$B,A14,'Test Case'!$L:$L,"Pass") -> 1 | H14: =COUNTIFS('Test Case'!$B:$B,A14,'Test Case'!$L:$L,"Fail") -> 0 | I14: =IF(F14=0,"Not Run",IF(H14>0,"Failed","Passed")) -> Passed
A15: TS-11 | B15: Kontrol Akses | C15: Verifikasi halaman admin tidak dapat diakses tanpa hak akses | D15: F-02 | E15: High | F15: =COUNTIF('Test Case'!$B:$B,A15) -> 2 | G15: =COUNTIFS('Test Case'!$B:$B,A15,'Test Case'!$L:$L,"Pass") -> 2 | H15: =COUNTIFS('Test Case'!$B:$B,A15,'Test Case'!$L:$L,"Fail") -> 0 | I15: =IF(F15=0,"Not Run",IF(H15>0,"Failed","Passed")) -> Passed
A16: TS-12 | B16: Kompatibilitas Browser | C16: Verifikasi tampilan & fungsi utama konsisten di Chrome, Firefox, dan Edge | D16: – | E16: Medium | F16: =COUNTIF('Test Case'!$B:$B,A16) -> 3 | G16: =COUNTIFS('Test Case'!$B:$B,A16,'Test Case'!$L:$L,"Pass") -> 3 | H16: =COUNTIFS('Test Case'!$B:$B,A16,'Test Case'!$L:$L,"Fail") -> 0 | I16: =IF(F16=0,"Not Run",IF(H16>0,"Failed","Passed")) -> Passed

Sheet Test Case
A1: Test Case – Sistem Informasi Desa Pangombusan
A2: Status: Pass / Fail / Blocked / Not Run | Evidence: nama file screenshot di folder /Evidence
A4: TC ID | B4: TS ID | C4: Module | D4: Test Case | E4: Type | F4: Priority | G4: Precondition | H4: Test Steps | I4: Test Data | J4: Expected Result | K4: Actual Result | L4: Status | M4: Bug ID | N4: Retest Result | O4: Tester | P4: Test Date
A5: TC-001 | B5: TS-01 | C5: =INDEX('Test Scenario'!$B:$B,MATCH(B5,'Test Scenario'!$A:$A,0)) -> Registrasi | D5: Registrasi dengan data valid | E5: Positive | F5: High | G5: User belum memiliki akun | H5: 1. Buka halaman website 2. Klik menu Registrasi 3. Isi semua field dengan data valid 4. Klik tombol Daftar | I5: Nama: Budi Santoso Email: budi.santoso@mail.com Password: Budi@2023 | J5: Akun berhasil dibuat dan sistem menampilkan halaman Login | K5: Sesuai dengan expected result. | L5: Pass | O5: =Cover!$C$8 -> Marshanda Kasih Simangunsong | P5: 45082
A6: TC-002 | B6: TS-01 | C6: =INDEX('Test Scenario'!$B:$B,MATCH(B6,'Test Scenario'!$A:$A,0)) -> Registrasi | D6: Registrasi dengan email yang sudah terdaftar | E6: Negative | F6: High | G6: Email budi.santoso@mail.com sudah terdaftar | H6: 1. Buka halaman Registrasi 2. Isi form dengan email yang sudah terdaftar 3. Klik tombol Daftar | I6: Email: budi.santoso@mail.com (sudah terdaftar) | J6: Sistem menampilkan pesan "Email sudah terdaftar" dan akun tidak dibuat | K6: Muncul halaman error database: "Duplicate entry 'budi.santoso@mail.com' for key 'email'" | L6: Fail | M6: BUG-001 | N6: Pass | O6: =Cover!$C$8 -> Marshanda Kasih Simangunsong | P6: 45082
A7: TC-003 | B7: TS-01 | C7: =INDEX('Test Scenario'!$B:$B,MATCH(B7,'Test Scenario'!$A:$A,0)) -> Registrasi | D7: Registrasi dengan semua field kosong | E7: Negative | F7: Medium | G7: User berada di halaman website | H7: 1. Buka halaman Registrasi 2. Biarkan semua field kosong 3. Klik tombol Daftar | I7: (kosong) | J7: Sistem menampilkan pesan validasi pada field wajib diisi | K7: Sesuai dengan expected result. | L7: Pass | O7: =Cover!$C$8 -> Marshanda Kasih Simangunsong | P7: 45082
A8: TC-004 | B8: TS-01 | C8: =INDEX('Test Scenario'!$B:$B,MATCH(B8,'Test Scenario'!$A:$A,0)) -> Registrasi | D8: Registrasi dengan format email tidak valid | E8: Negative | F8: Medium | G8: User berada di halaman website | H8: 1. Buka halaman Registrasi 2. Isi email tanpa domain 3. Klik tombol Daftar | I8: Email: budi.santoso@ | J8: Sistem menolak dan menampilkan pesan format email tidak valid | K8: Sesuai dengan expected result. | L8: Pass | O8: =Cover!$C$8 -> Marshanda Kasih Simangunsong | P8: 45082
A9: TC-005 | B9: TS-01 | C9: =INDEX('Test Scenario'!$B:$B,MATCH(B9,'Test Scenario'!$A:$A,0)) -> Registrasi | D9: Registrasi dengan password kurang dari 8 karakter | E9: Negative | F9: Medium | G9: User berada di halaman website | H9: 1. Buka halaman Registrasi 2. Isi data valid dengan password 1 karakter 3. Klik tombol Daftar | I9: Password: 1 | J9: Sistem menolak dan menampilkan pesan "Password minimal 8 karakter" | K9: Registrasi berhasil dan akun dibuat dengan password 1 karakter | L9: Fail | M9: BUG-002 | N9: Pass | O9: =Cover!$C$8 -> Marshanda Kasih Simangunsong | P9: 45082
A10: TC-006 | B10: TS-02 | C10: =INDEX('Test Scenario'!$B:$B,MATCH(B10,'Test Scenario'!$A:$A,0)) -> Login | D10: Login admin dengan kredensial valid | E10: Positive | F10: High | G10: Akun admin sudah terdaftar | H10: 1. Pilih menu Login 2. Isi email dan password admin 3. Klik tombol Login | I10: Email: admin@desa.test Password: Admin@123 | J10: Login berhasil dan sistem menampilkan halaman Home | K10: Sesuai dengan expected result. | L10: Pass | O10: =Cover!$C$8 -> Marshanda Kasih Simangunsong | P10: 45082
A11: TC-007 | B11: TS-02 | C11: =INDEX('Test Scenario'!$B:$B,MATCH(B11,'Test Scenario'!$A:$A,0)) -> Login | D11: Login user dengan kredensial valid | E11: Positive | F11: High | G11: Akun user sudah terdaftar | H11: 1. Pilih menu Login 2. Isi email dan password user 3. Klik tombol Login | I11: Email: budi.santoso@mail.com Password: Budi@2023 | J11: Login berhasil dan sistem menampilkan halaman Home | K11: Sesuai dengan expected result. | L11: Pass | O11: =Cover!$C$8 -> Marshanda Kasih Simangunsong | P11: 45082
A12: TC-008 | B12: TS-02 | C12: =INDEX('Test Scenario'!$B:$B,MATCH(B12,'Test Scenario'!$A:$A,0)) -> Login | D12: Login dengan form kosong | E12: Negative | F12: Medium | G12: User berada di halaman website | H12: 1. Pilih menu Login 2. Biarkan form kosong 3. Klik tombol Login | I12: (kosong) | J12: Sistem menampilkan pesan "Isi form" | K12: Sesuai dengan expected result. | L12: Pass | O12: =Cover!$C$8 -> Marshanda Kasih Simangunsong | P12: 45082
A13: TC-009 | B13: TS-02 | C13: =INDEX('Test Scenario'!$B:$B,MATCH(B13,'Test Scenario'!$A:$A,0)) -> Login | D13: Login dengan email salah dan password benar | E13: Negative | F13: High | G13: User berada di halaman website | H13: 1. Pilih menu Login 2. Isi email yang tidak terdaftar dan password benar 3. Klik tombol Login | I13: Email: salah@mail.com Password: Admin@123 | J13: Login ditolak dan sistem menampilkan "Invalid login" | K13: Sesuai dengan expected result. | L13: Pass | O13: =Cover!$C$8 -> Marshanda Kasih Simangunsong | P13: 45082
A14: TC-010 | B14: TS-02 | C14: =INDEX('Test Scenario'!$B:$B,MATCH(B14,'Test Scenario'!$A:$A,0)) -> Login | D14: Login dengan email benar dan password salah | E14: Negative | F14: High | G14: User berada di halaman website | H14: 1. Pilih menu Login 2. Isi email benar dan password salah 3. Klik tombol Login | I14: Email: admin@desa.test Password: salah123 | J14: Login ditolak dan sistem menampilkan "Invalid login" | K14: Sesuai dengan expected result. | L14: Pass | O14: =Cover!$C$8 -> Marshanda Kasih Simangunsong | P14: 45082
A15: TC-011 | B15: TS-02 | C15: =INDEX('Test Scenario'!$B:$B,MATCH(B15,'Test Scenario'!$A:$A,0)) -> Login | D15: Login dengan input SQL injection pada field email | E15: Negative | F15: High | G15: User berada di halaman website | H15: 1. Pilih menu Login 2. Isi email dengan string SQL injection 3. Klik tombol Login | I15: Email: ' OR '1'='1 Password: sembarang | J15: Login ditolak dan sistem menampilkan "Invalid login" | K15: Sesuai dengan expected result. | L15: Pass | O15: =Cover!$C$8 -> Marshanda Kasih Simangunsong | P15: 45082
A16: TC-012 | B16: TS-03 | C16: =INDEX('Test Scenario'!$B:$B,MATCH(B16,'Test Scenario'!$A:$A,0)) -> Kelola Berita | D16: Guest melihat daftar berita terbaru | E16: Positive | F16: Medium | G16: Terdapat minimal 1 berita | H16: 1. Buka halaman Home 2. Klik menu Berita Terbaru | I16: - | J16: Halaman berita menampilkan daftar berita diurutkan dari yang terbaru | K16: Sesuai dengan expected result. | L16: Pass | O16: =Cover!$C$8 -> Marshanda Kasih Simangunsong | P16: 45082
A17: TC-013 | B17: TS-03 | C17: =INDEX('Test Scenario'!$B:$B,MATCH(B17,'Test Scenario'!$A:$A,0)) -> Kelola Berita | D17: Admin menambah berita dengan data valid | E17: Positive | F17: High | G17: Login sebagai admin | H17: 1. Buka menu Kelola Berita 2. Klik Tambah Berita 3. Isi judul, isi, dan unggah gambar 4. Klik Simpan | I17: Judul: Gotong Royong Desa Gambar: berita1.jpg (200 KB) | J17: Berita tersimpan dan tampil di daftar berita terbaru | K17: Sesuai dengan expected result. | L17: Pass | O17: =Cover!$C$8 -> Marshanda Kasih Simangunsong | P17: 45082
A18: TC-014 | B18: TS-03 | C18: =INDEX('Test Scenario'!$B:$B,MATCH(B18,'Test Scenario'!$A:$A,0)) -> Kelola Berita | D18: Admin menambah berita dengan file bukan gambar | E18: Negative | F18: Medium | G18: Login sebagai admin | H18: 1. Buka menu Kelola Berita 2. Klik Tambah Berita 3. Isi judul dan isi, unggah file PDF pada field gambar 4. Klik Simpan | I18: File: berita.pdf (150 KB) | J18: Sistem menolak file dan menampilkan pesan "File harus berupa gambar (JPG/PNG)" | K18: File PDF diterima, berita tersimpan, thumbnail di halaman Home tampil sebagai broken image | L18: Fail | M18: BUG-003 | N18: Pass | O18: =Cover!$C$8 -> Marshanda Kasih Simangunsong | P18: 45082
A19: TC-015 | B19: TS-03 | C19: =INDEX('Test Scenario'!$B:$B,MATCH(B19,'Test Scenario'!$A:$A,0)) -> Kelola Berita | D19: Admin menambah berita dengan judul kosong | E19: Negative | F19: Medium | G19: Login sebagai admin | H19: 1. Buka menu Kelola Berita 2. Klik Tambah Berita 3. Kosongkan judul, isi konten 4. Klik Simpan | I19: Judul: (kosong) | J19: Sistem menampilkan pesan validasi judul wajib diisi | K19: Sesuai dengan expected result. | L19: Pass | O19: =Cover!$C$8 -> Marshanda Kasih Simangunsong | P19: 45082
A20: TC-016 | B20: TS-03 | C20: =INDEX('Test Scenario'!$B:$B,MATCH(B20,'Test Scenario'!$A:$A,0)) -> Kelola Berita | D20: Admin mengedit berita | E20: Positive | F20: High | G20: Login sebagai admin; berita tersedia | H20: 1. Buka menu Kelola Berita 2. Klik Edit pada salah satu berita 3. Ubah judul 4. Klik Simpan | I20: Judul baru: Gotong Royong Dusun I | J20: Perubahan tersimpan dan tampil pada daftar berita | K20: Sesuai dengan expected result. | L20: Pass | O20: =Cover!$C$8 -> Marshanda Kasih Simangunsong | P20: 45082
A21: TC-017 | B21: TS-03 | C21: =INDEX('Test Scenario'!$B:$B,MATCH(B21,'Test Scenario'!$A:$A,0)) -> Kelola Berita | D21: Admin menghapus berita | E21: Positive | F21: High | G21: Login sebagai admin; berita tersedia | H21: 1. Buka menu Kelola Berita 2. Klik Hapus pada salah satu berita 3. Konfirmasi hapus | I21: - | J21: Dialog konfirmasi tampil; setelah dikonfirmasi berita terhapus dari daftar | K21: Berita langsung terhapus tanpa dialog konfirmasi | L21: Fail | M21: BUG-004 | N21: Pass | O21: =Cover!$C$8 -> Marshanda Kasih Simangunsong | P21: 45082
A22: TC-018 | B22: TS-04 | C22: =INDEX('Test Scenario'!$B:$B,MATCH(B22,'Test Scenario'!$A:$A,0)) -> Kelola Pengumuman | D22: Admin menambah pengumuman dengan data valid | E22: Positive | F22: Medium | G22: Login sebagai admin | H22: 1. Buka menu Kelola Pengumuman 2. Klik Tambah 3. Isi judul dan isi pengumuman 4. Klik Simpan | I22: Judul: Jadwal Posyandu Juni | J22: Pengumuman tersimpan dan tampil pada halaman Pengumuman | K22: Sesuai dengan expected result. | L22: Pass | O22: =Cover!$C$8 -> Marshanda Kasih Simangunsong | P22: 45082
A23: TC-019 | B23: TS-04 | C23: =INDEX('Test Scenario'!$B:$B,MATCH(B23,'Test Scenario'!$A:$A,0)) -> Kelola Pengumuman | D23: Admin mengedit pengumuman | E23: Positive | F23: Medium | G23: Login sebagai admin; pengumuman tersedia | H23: 1. Buka menu Kelola Pengumuman 2. Klik Edit 3. Ubah isi pengumuman 4. Klik Simpan | I23: Isi: jadwal diperbarui | J23: Perubahan tersimpan dan tampil pada halaman Pengumuman | K23: Sesuai dengan expected result. | L23: Pass | O23: =Cover!$C$8 -> Marshanda Kasih Simangunsong | P23: 45082
A24: TC-020 | B24: TS-04 | C24: =INDEX('Test Scenario'!$B:$B,MATCH(B24,'Test Scenario'!$A:$A,0)) -> Kelola Pengumuman | D24: Admin menghapus pengumuman | E24: Positive | F24: Medium | G24: Login sebagai admin; pengumuman tersedia | H24: 1. Buka menu Kelola Pengumuman 2. Klik Hapus 3. Konfirmasi hapus | I24: - | J24: Pengumuman terhapus dari daftar | K24: Sesuai dengan expected result. | L24: Pass | O24: =Cover!$C$8 -> Marshanda Kasih Simangunsong | P24: 45082
A25: TC-021 | B25: TS-04 | C25: =INDEX('Test Scenario'!$B:$B,MATCH(B25,'Test Scenario'!$A:$A,0)) -> Kelola Pengumuman | D25: Admin menambah pengumuman dengan judul sangat panjang | E25: Negative | F25: Low | G25: Login sebagai admin | H25: 1. Buka menu Kelola Pengumuman 2. Klik Tambah 3. Isi judul lebih dari 200 karakter 4. Klik Simpan 5. Buka halaman Pengumuman | I25: Judul: 250 karakter tanpa spasi | J25: Judul dipotong/wrap dan layout halaman tetap rapi | K25: Judul melebihi lebar container sehingga layout bergeser dan tabel pengumuman terpotong | L25: Fail | M25: BUG-005 | N25: Pass | O25: =Cover!$C$8 -> Marshanda Kasih Simangunsong | P25: 45082
A26: TC-022 | B26: TS-05 | C26: =INDEX('Test Scenario'!$B:$B,MATCH(B26,'Test Scenario'!$A:$A,0)) -> Surat Pengantar KTP – Pengajuan | D26: User mengajukan surat pengantar KTP dengan data valid | E26: Positive | F26: High | G26: Login sebagai user | H26: 1. Buka menu Surat Pengantar KTP 2. Klik Ajukan Surat 3. Isi form dengan data valid 4. Klik Kirim | I26: Nama: Budi Santoso NIK: 1207010101900001 (dummy) | J26: Pengajuan tersimpan dengan status "Menunggu persetujuan" | K26: Sesuai dengan expected result. | L26: Pass | O26: =Cover!$C$8 -> Marshanda Kasih Simangunsong | P26: 45083
A27: TC-023 | B27: TS-05 | C27: =INDEX('Test Scenario'!$B:$B,MATCH(B27,'Test Scenario'!$A:$A,0)) -> Surat Pengantar KTP – Pengajuan | D27: Pengajuan surat dengan NIK kurang dari 16 digit | E27: Negative | F27: High | G27: Login sebagai user | H27: 1. Buka menu Surat Pengantar KTP 2. Klik Ajukan Surat 3. Isi NIK kurang dari 16 digit 4. Klik Kirim | I27: NIK: 1207010101 (10 digit) | J27: Sistem menolak dan menampilkan pesan "NIK harus 16 digit" | K27: Pengajuan berhasil tersimpan dengan NIK 10 digit | L27: Fail | M27: BUG-006 | N27: Pass | O27: =Cover!$C$8 -> Marshanda Kasih Simangunsong | P27: 45083
A28: TC-024 | B28: TS-05 | C28: =INDEX('Test Scenario'!$B:$B,MATCH(B28,'Test Scenario'!$A:$A,0)) -> Surat Pengantar KTP – Pengajuan | D28: Pengajuan surat dengan NIK berisi huruf | E28: Negative | F28: High | G28: Login sebagai user | H28: 1. Buka menu Surat Pengantar KTP 2. Klik Ajukan Surat 3. Isi NIK dengan huruf dan angka 4. Klik Kirim | I28: NIK: 12070101ABCD0001 | J28: Sistem menolak input NIK non-numerik | K28: Sesuai dengan expected result. | L28: Pass | O28: =Cover!$C$8 -> Marshanda Kasih Simangunsong | P28: 45083
A29: TC-025 | B29: TS-05 | C29: =INDEX('Test Scenario'!$B:$B,MATCH(B29,'Test Scenario'!$A:$A,0)) -> Surat Pengantar KTP – Pengajuan | D29: User melihat daftar surat pengantar KTP miliknya | E29: Positive | F29: Medium | G29: Login sebagai user; ada pengajuan | H29: 1. Buka menu Surat Pengantar KTP 2. Lihat daftar pengajuan | I29: - | J29: Daftar pengajuan beserta status tampil sesuai akun user | K29: Sesuai dengan expected result. | L29: Pass | O29: =Cover!$C$8 -> Marshanda Kasih Simangunsong | P29: 45083
A30: TC-026 | B30: TS-06 | C30: =INDEX('Test Scenario'!$B:$B,MATCH(B30,'Test Scenario'!$A:$A,0)) -> Surat Pengantar KTP – Approval | D30: Admin menyetujui pengajuan surat | E30: Positive | F30: High | G30: Login sebagai admin; ada pengajuan berstatus Menunggu | H30: 1. Buka menu Surat Pengantar KTP 2. Pilih pengajuan 3. Klik Setujui | I30: - | J30: Status berubah menjadi "Disetujui" dan pengajuan masuk daftar approve | K30: Sesuai dengan expected result. | L30: Pass | O30: =Cover!$C$8 -> Marshanda Kasih Simangunsong | P30: 45083
A31: TC-027 | B31: TS-06 | C31: =INDEX('Test Scenario'!$B:$B,MATCH(B31,'Test Scenario'!$A:$A,0)) -> Surat Pengantar KTP – Approval | D31: Admin menolak pengajuan surat | E31: Positive | F31: High | G31: Login sebagai admin; ada pengajuan berstatus Menunggu | H31: 1. Buka menu Surat Pengantar KTP 2. Pilih pengajuan 3. Klik Tolak | I31: - | J31: Status berubah menjadi "Ditolak" dan pengajuan masuk daftar reject | K31: Sesuai dengan expected result. | L31: Pass | O31: =Cover!$C$8 -> Marshanda Kasih Simangunsong | P31: 45083
A32: TC-028 | B32: TS-06 | C32: =INDEX('Test Scenario'!$B:$B,MATCH(B32,'Test Scenario'!$A:$A,0)) -> Surat Pengantar KTP – Approval | D32: Admin melihat daftar surat yang disetujui | E32: Positive | F32: Medium | G32: Login sebagai admin | H32: 1. Buka menu Approve Surat | I32: - | J32: Daftar surat berstatus Disetujui tampil lengkap | K32: Sesuai dengan expected result. | L32: Pass | O32: =Cover!$C$8 -> Marshanda Kasih Simangunsong | P32: 45083
A33: TC-029 | B33: TS-06 | C33: =INDEX('Test Scenario'!$B:$B,MATCH(B33,'Test Scenario'!$A:$A,0)) -> Surat Pengantar KTP – Approval | D33: Admin melihat daftar surat yang ditolak | E33: Positive | F33: Medium | G33: Login sebagai admin | H33: 1. Buka menu Reject Surat | I33: - | J33: Daftar surat berstatus Ditolak tampil lengkap | K33: Sesuai dengan expected result. | L33: Pass | O33: =Cover!$C$8 -> Marshanda Kasih Simangunsong | P33: 45083
A34: TC-030 | B34: TS-07 | C34: =INDEX('Test Scenario'!$B:$B,MATCH(B34,'Test Scenario'!$A:$A,0)) -> Kelola Saran | D34: Pengunjung mengirim saran dengan data valid | E34: Positive | F34: Medium | G34: User berada di halaman website | H34: 1. Buka halaman Saran 2. Isi nama dan pesan saran 3. Klik Kirim | I34: Pesan: Mohon jalan dusun II diperbaiki | J34: Saran tersimpan dan sistem menampilkan notifikasi berhasil | K34: Sesuai dengan expected result. | L34: Pass | O34: =Cover!$C$8 -> Marshanda Kasih Simangunsong | P34: 45083
A35: TC-031 | B35: TS-07 | C35: =INDEX('Test Scenario'!$B:$B,MATCH(B35,'Test Scenario'!$A:$A,0)) -> Kelola Saran | D35: Pengunjung mengirim saran berisi script HTML | E35: Negative | F35: High | G35: Login admin tersedia untuk verifikasi | H35: 1. Buka halaman Saran sebagai guest 2. Isi pesan dengan tag script 3. Klik Kirim 4. Login sebagai admin dan buka Kelola Saran | I35: Pesan: <script>alert('XSS')</script> | J35: Input disanitasi dan tampil sebagai teks biasa; script tidak dieksekusi | K35: Popup alert 'XSS' muncul setiap admin membuka halaman Kelola Saran (script tereksekusi) | L35: Fail | M35: BUG-007 | N35: Pass | O35: =Cover!$C$8 -> Marshanda Kasih Simangunsong | P35: 45083
A36: TC-032 | B36: TS-07 | C36: =INDEX('Test Scenario'!$B:$B,MATCH(B36,'Test Scenario'!$A:$A,0)) -> Kelola Saran | D36: Admin melihat daftar saran | E36: Positive | F36: Medium | G36: Login sebagai admin | H36: 1. Buka menu Kelola Saran | I36: - | J36: Daftar saran tampil lengkap | K36: Sesuai dengan expected result. | L36: Pass | O36: =Cover!$C$8 -> Marshanda Kasih Simangunsong | P36: 45083
A37: TC-033 | B37: TS-07 | C37: =INDEX('Test Scenario'!$B:$B,MATCH(B37,'Test Scenario'!$A:$A,0)) -> Kelola Saran | D37: Admin mengedit saran | E37: Positive | F37: Low | G37: Login sebagai admin; saran tersedia | H37: 1. Buka menu Kelola Saran 2. Klik Edit 3. Ubah isi saran 4. Klik Simpan | I37: - | J37: Perubahan tersimpan | K37: Sesuai dengan expected result. | L37: Pass | O37: =Cover!$C$8 -> Marshanda Kasih Simangunsong | P37: 45083
A38: TC-034 | B38: TS-07 | C38: =INDEX('Test Scenario'!$B:$B,MATCH(B38,'Test Scenario'!$A:$A,0)) -> Kelola Saran | D38: Admin menghapus saran | E38: Positive | F38: Medium | G38: Login sebagai admin; saran tersedia | H38: 1. Buka menu Kelola Saran 2. Klik Hapus 3. Konfirmasi hapus | I38: - | J38: Saran terhapus dari daftar | K38: Sesuai dengan expected result. | L38: Pass | O38: =Cover!$C$8 -> Marshanda Kasih Simangunsong | P38: 45083
A39: TC-035 | B39: TS-08 | C39: =INDEX('Test Scenario'!$B:$B,MATCH(B39,'Test Scenario'!$A:$A,0)) -> Kelola Galeri | D39: Admin menambah foto galeri dengan file valid | E39: Positive | F39: Medium | G39: Login sebagai admin | H39: 1. Buka menu Kelola Galeri 2. Klik Tambah Foto 3. Pilih file JPG dan isi keterangan 4. Klik Simpan | I39: File: kegiatan.jpg (1 MB) | J39: Foto tersimpan dan tampil di halaman Galeri | K39: Sesuai dengan expected result. | L39: Pass | O39: =Cover!$C$8 -> Marshanda Kasih Simangunsong | P39: 45083
A40: TC-036 | B40: TS-08 | C40: =INDEX('Test Scenario'!$B:$B,MATCH(B40,'Test Scenario'!$A:$A,0)) -> Kelola Galeri | D40: Admin mengunggah foto galeri berukuran lebih dari 5 MB | E40: Negative | F40: Medium | G40: Login sebagai admin | H40: 1. Buka menu Kelola Galeri 2. Klik Tambah Foto 3. Pilih file lebih dari 5 MB 4. Klik Simpan | I40: File: besar.jpg (8 MB) | J40: Sistem menolak dan menampilkan pesan ukuran maksimum file | K40: Sesuai dengan expected result. | L40: Pass | O40: =Cover!$C$8 -> Marshanda Kasih Simangunsong | P40: 45083
A41: TC-037 | B41: TS-08 | C41: =INDEX('Test Scenario'!$B:$B,MATCH(B41,'Test Scenario'!$A:$A,0)) -> Kelola Galeri | D41: Admin menghapus foto galeri | E41: Positive | F41: Medium | G41: Login sebagai admin; foto tersedia | H41: 1. Buka menu Kelola Galeri 2. Klik Hapus 3. Konfirmasi hapus | I41: - | J41: Foto terhapus dari galeri | K41: Sesuai dengan expected result. | L41: Pass | O41: =Cover!$C$8 -> Marshanda Kasih Simangunsong | P41: 45083
...

Sheet Bug Report
A1: Bug Report – Sistem Informasi Desa Pangombusan
A2: Lifecycle: Open → Fixed → Closed | Reopened jika retest gagal | Evidence: nama file screenshot di folder /Evidence
A4: Bug ID | B4: Bug Title | C4: Module | D4: Related TC | E4: Severity | F4: Priority | G4: Status | H4: Environment | I4: Steps to Reproduce | J4: Expected Result | K4: Actual Result | L4: Reported By | M4: Reported Date | N4: Assigned To | O4: Retest Date | P4: Evidence | Q4: Remarks
A5: BUG-001 | B5: Pesan error database tampil ke user saat registrasi dengan email yang sudah terdaftar | C5: Registrasi | D5: TC-002 | E5: High | F5: High | G5: Closed | H5: Windows 11 / Chrome / Apache + MySQL | I5: 1. Buka halaman Registrasi 2. Isi form dengan email yang sudah terdaftar (budi.santoso@mail.com) 3. Klik tombol Daftar | J5: Sistem menampilkan pesan "Email sudah terdaftar" dan tetap di halaman Registrasi | K5: Muncul halaman error: "Duplicate entry 'budi.santoso@mail.com' for key 'email'" (informasi struktur database terekspos) | L5: =Cover!$C$8 -> Marshanda Kasih Simangunsong | M5: 45082 | N5: Developer | O5: 45086 | P5: https://drive.google.com/file/d/17U5Qi8IridrwjYqj32izNL5BlYfuMxTQ/view?usp=sharing | Q5: Fixed oleh developer: ditambahkan pengecekan email sebelum insert. Retest 09 Jun: Pass.
A6: BUG-002 | B6: Sistem menerima password 1 karakter saat registrasi | C6: Registrasi | D6: TC-005 | E6: Medium | F6: Medium | G6: Closed | H6: Windows 11 / Chrome / Apache + MySQL | I6: 1. Buka halaman Registrasi 2. Isi data valid dengan password "1" 3. Klik tombol Daftar | J6: Sistem menolak dengan pesan "Password minimal 8 karakter" | K6: Akun berhasil dibuat dengan password 1 karakter | L6: =Cover!$C$8 -> Marshanda Kasih Simangunsong | M6: 45082 | N6: Developer | O6: 45086 | P6: https://drive.google.com/file/d/1UdRfoFEKHp4ud183ycouITzWUTWYa5T6/view?usp=sharing | Q6: Validasi panjang password ditambahkan. Retest 09 Jun: Pass.
A7: BUG-003 | B7: Upload berita menerima file non-gambar (PDF) | C7: Kelola Berita | D7: TC-014 | E7: Medium | F7: Medium | G7: Closed | H7: Windows 11 / Chrome / Apache + MySQL | I7: 1. Login sebagai admin 2. Buka Kelola Berita > Tambah Berita 3. Isi judul dan isi, unggah file berita.pdf pada field gambar 4. Klik Simpan 5. Buka halaman Home | J7: File ditolak dengan pesan "File harus berupa gambar (JPG/PNG)" | K7: Berita tersimpan dan thumbnail di Home tampil sebagai broken image | L7: =Cover!$C$8 -> Marshanda Kasih Simangunsong | M7: 45082 | N7: Developer | O7: 45086 | P7: https://drive.google.com/file/d/13TgHAGv8WrKaIJdHIHrEOprHsJlsLy3Z/view?usp=sharing | Q7: Perlu validasi tipe file (ekstensi dan MIME type) di sisi server.
A8: BUG-004 | B8: Berita terhapus tanpa dialog konfirmasi | C8: Kelola Berita | D8: TC-017 | E8: Medium | F8: Medium | G8: Closed | H8: Windows 11 / Chrome / Apache + MySQL | I8: 1. Login sebagai admin 2. Buka Kelola Berita 3. Klik tombol Hapus pada salah satu berita | J8: Dialog konfirmasi tampil sebelum data dihapus | K8: Berita langsung terhapus tanpa konfirmasi | L8: =Cover!$C$8 -> Marshanda Kasih Simangunsong | M8: 45082 | N8: Developer | O8: 45086 | P8: https://drive.google.com/file/d/1lQMSLJS6qEgKXzV3OyQ00Tnty8Y9REjH/view?usp=sharing | Q8: Dialog konfirmasi ditambahkan. Retest 09 Jun: Pass.
A9: BUG-005 | B9: Judul pengumuman panjang merusak layout halaman Pengumuman | C9: Kelola Pengumuman | D9: TC-021 | E9: Low | F9: Low | G9: Closed | H9: Windows 11 / Chrome / Apache + MySQL | I9: 1. Login sebagai admin 2. Tambah pengumuman dengan judul 250 karakter tanpa spasi 3. Klik Simpan 4. Buka halaman Pengumuman | J9: Judul dipotong atau dibungkus; layout tetap rapi | K9: Judul melebihi lebar container; layout bergeser dan tabel terpotong | L9: =Cover!$C$8 -> Marshanda Kasih Simangunsong | M9: 45082 | N9: Developer | O9: 45086 | P9: https://drive.google.com/file/d/1n9gnTUgtRldUtMUjPUkc0haR-zjA-zcc/view?usp=sharing | Q9: Saran: terapkan word-break/overflow-wrap pada CSS dan batasi panjang judul.
A10: BUG-006 | B10: Field NIK pada pengajuan surat KTP menerima kurang dari 16 digit | C10: Surat Pengantar KTP | D10: TC-023 | E10: High | F10: High | G10: Closed | H10: Windows 11 / Chrome / Apache + MySQL | I10: 1. Login sebagai user 2. Buka Surat Pengantar KTP > Ajukan Surat 3. Isi NIK dengan 10 digit (1207010101) 4. Klik Kirim | J10: Sistem menolak dengan pesan "NIK harus 16 digit" | K10: Pengajuan tersimpan dengan NIK 10 digit | L10: =Cover!$C$8 -> Marshanda Kasih Simangunsong | M10: 45083 | N10: Developer | O10: 45086 | P10: https://drive.google.com/file/d/1HTeJm9TPfnBqsIBat5LXs_wKY_dTzplm/view?usp=drive_link | Q10: Retest 09 Jun: NIK 17 digit sudah ditolak, namun NIK 10 digit masih diterima (validasi hanya batas maksimum). Status: Reopened.
A11: BUG-007 | B11: Stored XSS pada form Saran: script tereksekusi di halaman Kelola Saran admin | C11: Kelola Saran | D11: TC-031 | E11: Critical | F11: High | G11: Closed | H11: Windows 11 / Chrome / Apache + MySQL | I11: 1. Buka halaman Saran sebagai guest 2. Isi pesan dengan <script>alert('XSS')</script> 3. Klik Kirim 4. Login sebagai admin dan buka Kelola Saran | J11: Input disanitasi/di-escape dan tampil sebagai teks biasa | K11: Popup alert muncul setiap kali admin membuka Kelola Saran; script tereksekusi di sesi admin | L11: =Cover!$C$8 -> Marshanda Kasih Simangunsong | M11: 45083 | N11: Developer | O11: 45086 | P11: https://drive.google.com/file/d/1ODZt--cexKM9fUHUMREs8W8cCaxB6UWe/view?usp=drive_link | Q11: Risiko: pencurian sesi admin. Rekomendasi: escape output (htmlspecialchars) dan sanitasi input.
A12: BUG-008 | B12: Halaman admin masih dapat dilihat dengan tombol Back setelah logout | C12: Logout | D12: TC-039 | E12: Medium | F12: Medium | G12: Closed | H12: Windows 11 / Chrome / Apache + MySQL | I12: 1. Login sebagai admin 2. Klik Logout 3. Klik tombol Back pada browser | J12: User diarahkan ke halaman Login; halaman admin tidak tampil | K12: Halaman dashboard admin masih tampil dari cache browser | L12: =Cover!$C$8 -> Marshanda Kasih Simangunsong | M12: 45083 | N12: Developer | O12: 45086 | P12: https://drive.google.com/file/d/1qQXsbaHL7iiRTCecvrlzIicvKcVTP_2M/view?usp=drive_link | Q12: Developer menambahkan header no-cache dan pengecekan sesi. Menunggu retest.

Sheet Test Summary
A1: Test Summary – Sistem Informasi Desa Pangombusan
A2: Seluruh angka dihitung otomatis dari sheet Test Case dan Bug Report
A4: 1. Hasil Eksekusi Test Case per Modul
A5: Module | B5: Total TC | C5: Pass | D5: Fail | E5: Not Run | F5: Pass Rate
A6: Registrasi | B6: =COUNTIF('Test Case'!$C:$C,A6) -> 5 | C6: =COUNTIFS('Test Case'!$C:$C,A6,'Test Case'!$L:$L,"Pass") -> 3 | D6: =COUNTIFS('Test Case'!$C:$C,A6,'Test Case'!$L:$L,"Fail") -> 2 | E6: =B6-C6-D6 -> 0 | F6: =IF(B6=0,0,C6/B6) -> 0.6
A7: Login | B7: =COUNTIF('Test Case'!$C:$C,A7) -> 6 | C7: =COUNTIFS('Test Case'!$C:$C,A7,'Test Case'!$L:$L,"Pass") -> 6 | D7: =COUNTIFS('Test Case'!$C:$C,A7,'Test Case'!$L:$L,"Fail") -> 0 | E7: =B7-C7-D7 -> 0 | F7: =IF(B7=0,0,C7/B7) -> 1
A8: Kelola Berita | B8: =COUNTIF('Test Case'!$C:$C,A8) -> 6 | C8: =COUNTIFS('Test Case'!$C:$C,A8,'Test Case'!$L:$L,"Pass") -> 4 | D8: =COUNTIFS('Test Case'!$C:$C,A8,'Test Case'!$L:$L,"Fail") -> 2 | E8: =B8-C8-D8 -> 0 | F8: =IF(B8=0,0,C8/B8) -> 0.66666667
A9: Kelola Pengumuman | B9: =COUNTIF('Test Case'!$C:$C,A9) -> 4 | C9: =COUNTIFS('Test Case'!$C:$C,A9,'Test Case'!$L:$L,"Pass") -> 3 | D9: =COUNTIFS('Test Case'!$C:$C,A9,'Test Case'!$L:$L,"Fail") -> 1 | E9: =B9-C9-D9 -> 0 | F9: =IF(B9=0,0,C9/B9) -> 0.75
A10: Surat Pengantar KTP – Pengajuan | B10: =COUNTIF('Test Case'!$C:$C,A10) -> 4 | C10: =COUNTIFS('Test Case'!$C:$C,A10,'Test Case'!$L:$L,"Pass") -> 3 | D10: =COUNTIFS('Test Case'!$C:$C,A10,'Test Case'!$L:$L,"Fail") -> 1 | E10: =B10-C10-D10 -> 0 | F10: =IF(B10=0,0,C10/B10) -> 0.75
A11: Surat Pengantar KTP – Approval | B11: =COUNTIF('Test Case'!$C:$C,A11) -> 4 | C11: =COUNTIFS('Test Case'!$C:$C,A11,'Test Case'!$L:$L,"Pass") -> 4 | D11: =COUNTIFS('Test Case'!$C:$C,A11,'Test Case'!$L:$L,"Fail") -> 0 | E11: =B11-C11-D11 -> 0 | F11: =IF(B11=0,0,C11/B11) -> 1
A12: Kelola Saran | B12: =COUNTIF('Test Case'!$C:$C,A12) -> 5 | C12: =COUNTIFS('Test Case'!$C:$C,A12,'Test Case'!$L:$L,"Pass") -> 4 | D12: =COUNTIFS('Test Case'!$C:$C,A12,'Test Case'!$L:$L,"Fail") -> 1 | E12: =B12-C12-D12 -> 0 | F12: =IF(B12=0,0,C12/B12) -> 0.8
A13: Kelola Galeri | B13: =COUNTIF('Test Case'!$C:$C,A13) -> 3 | C13: =COUNTIFS('Test Case'!$C:$C,A13,'Test Case'!$L:$L,"Pass") -> 3 | D13: =COUNTIFS('Test Case'!$C:$C,A13,'Test Case'!$L:$L,"Fail") -> 0 | E13: =B13-C13-D13 -> 0 | F13: =IF(B13=0,0,C13/B13) -> 1
A14: Logout | B14: =COUNTIF('Test Case'!$C:$C,A14) -> 2 | C14: =COUNTIFS('Test Case'!$C:$C,A14,'Test Case'!$L:$L,"Pass") -> 1 | D14: =COUNTIFS('Test Case'!$C:$C,A14,'Test Case'!$L:$L,"Fail") -> 1 | E14: =B14-C14-D14 -> 0 | F14: =IF(B14=0,0,C14/B14) -> 0.5
A15: Halaman Publik | B15: =COUNTIF('Test Case'!$C:$C,A15) -> 1 | C15: =COUNTIFS('Test Case'!$C:$C,A15,'Test Case'!$L:$L,"Pass") -> 1 | D15: =COUNTIFS('Test Case'!$C:$C,A15,'Test Case'!$L:$L,"Fail") -> 0 | E15: =B15-C15-D15 -> 0 | F15: =IF(B15=0,0,C15/B15) -> 1
A16: Kontrol Akses | B16: =COUNTIF('Test Case'!$C:$C,A16) -> 2 | C16: =COUNTIFS('Test Case'!$C:$C,A16,'Test Case'!$L:$L,"Pass") -> 2 | D16: =COUNTIFS('Test Case'!$C:$C,A16,'Test Case'!$L:$L,"Fail") -> 0 | E16: =B16-C16-D16 -> 0 | F16: =IF(B16=0,0,C16/B16) -> 1
A17: Kompatibilitas Browser | B17: =COUNTIF('Test Case'!$C:$C,A17) -> 3 | C17: =COUNTIFS('Test Case'!$C:$C,A17,'Test Case'!$L:$L,"Pass") -> 3 | D17: =COUNTIFS('Test Case'!$C:$C,A17,'Test Case'!$L:$L,"Fail") -> 0 | E17: =B17-C17-D17 -> 0 | F17: =IF(B17=0,0,C17/B17) -> 1
A18: TOTAL | B18: =SUM(B6:B17) -> 45 | C18: =SUM(C6:C17) -> 37 | D18: =SUM(D6:D17) -> 8 | E18: =SUM(E6:E17) -> 0 | F18: =IF(B18=0,0,C18/B18) -> 0.82222222
A21: 2. Defect berdasarkan Severity
A22: Severity | B22: Total | C22: Belum Closed
A23: Critical | B23: =COUNTIF('Bug Report'!$E:$E,A23) -> 1 | C23: =COUNTIFS('Bug Report'!$E:$E,A23,'Bug Report'!$G:$G,"<>Closed") -> 0
A24: High | B24: =COUNTIF('Bug Report'!$E:$E,A24) -> 2 | C24: =COUNTIFS('Bug Report'!$E:$E,A24,'Bug Report'!$G:$G,"<>Closed") -> 0
A25: Medium | B25: =COUNTIF('Bug Report'!$E:$E,A25) -> 4 | C25: =COUNTIFS('Bug Report'!$E:$E,A25,'Bug Report'!$G:$G,"<>Closed") -> 0
A26: Low | B26: =COUNTIF('Bug Report'!$E:$E,A26) -> 1 | C26: =COUNTIFS('Bug Report'!$E:$E,A26,'Bug Report'!$G:$G,"<>Closed") -> 0
A27: TOTAL | B27: =SUM(B23:B26) -> 8 | C27: =SUM(C23:C26) -> 0
A30: 3. Defect berdasarkan Status
A31: Status | B31: Total
A32: Open | B32: =COUNTIF('Bug Report'!$G:$G,A32) -> 0
A33: In Progress | B33: =COUNTIF('Bug Report'!$G:$G,A33) -> 0
A34: Fixed | B34: =COUNTIF('Bug Report'!$G:$G,A34) -> 0
A35: Reopened | B35: =COUNTIF('Bug Report'!$G:$G,A35) -> 0
A36: Closed | B36: =COUNTIF('Bug Report'!$G:$G,A36) -> 8
A38: 4. Metrik Utama
A39: Total Test Case | B39: =B18 -> 45
A40: Pass Rate | B40: =F18 -> 0.82222222
A41: Total Defect | B41: =B27 -> 8
A42: Defect Closure Rate | B42: =IF(B27=0,0,B36/B27) -> 1
A43: Defect Kritis/High Belum Closed | B43: =C23+C24 -> 0
